<sdf version='1.6'>
  <model name='crane_x7'>
    <link name='base_link'>
      <pose frame=''>0 0 0.0025 0 -0 0</pose>
      <inertial>
        <pose frame=''>-0.00669 4.9e-05 0.022855 0 -0 0</pose>
        <mass>0.388313</mass>
        <inertia>
          <ixx>2</ixx>
          <ixy>2.64698e-23</ixy>
          <ixz>-1.35525e-20</ixz>
          <iyy>2</iyy>
          <iyz>-5.29396e-23</iyz>
          <izz>2</izz>
        </inertia>
      </inertial>
      <collision name='base_link_fixed_joint_lump__crane_x7_mounting_plate_link_collision'>
        <pose frame=''>0 0 0 0 -0 0</pose>
        <geometry>
          <mesh>
            <scale>1 1 1</scale>
            <uri>model://meshes/collision/mounting_plate.stl</uri>
          </mesh>
        </geometry>
      </collision>
      <collision name='base_link_fixed_joint_lump__crane_x7_shoulder_fixed_part_link_collision_1'>
        <pose frame=''>0 0 0.005 0 -0 0</pose>
        <geometry>
          <mesh>
            <scale>1 1 1</scale>
            <uri>model://meshes/collision/base_fixed_part.stl</uri>
          </mesh>
        </geometry>
      </collision>
      <visual name='base_link_fixed_joint_lump__crane_x7_mounting_plate_link_visual'>
        <pose frame=''>0 0 0 0 -0 0</pose>
        <geometry>
          <mesh>
            <scale>1 1 1</scale>
            <uri>model://meshes/visual/mounting_plate.stl</uri>
          </mesh>
        </geometry>
        <material>
          <script>
            <name>Gazebo/Grey</name>
          </script>
        </material>
      </visual>
      <visual name='base_link_fixed_joint_lump__crane_x7_shoulder_fixed_part_link_visual_1'>
        <pose frame=''>0 0 0.005 0 -0 0</pose>
        <geometry>
          <mesh>
            <scale>1 1 1</scale>
            <uri>model://meshes/visual/base_fixed_part.stl</uri>
          </mesh>
        </geometry>
        <material>
          <script>
            <name>Gazebo/Red</name>
          </script>
        </material>
      </visual>
    </link>
    <link name='crane_x7_shoulder_revolute_part_link'>
      <pose frame=''>0 0 0.041 0 -0 0</pose>
      <inertial>
        <pose frame=''>1.3e-05 -0.000407 0.046345 0 -0 0</pose>
        <mass>0.235377</mass>
        <inertia>
          <ixx>1</ixx>
          <ixy>0</ixy>
          <ixz>0</ixz>
          <iyy>1</iyy>
          <iyz>0</iyz>
          <izz>1</izz>
        </inertia>
      </inertial>
      <collision name='crane_x7_shoulder_revolute_part_link_collision'>
        <pose frame=''>0 0 0 0 -0 3.14159</pose>
        <geometry>
          <mesh>
            <scale>1 1 1</scale>
            <uri>model://meshes/collision/base_revolute_part.stl</uri>
          </mesh>
        </geometry>
      </collision>
      <visual name='crane_x7_shoulder_revolute_part_link_visual'>
        <pose frame=''>0 0 0 0 -0 3.14159</pose>
        <geometry>
          <mesh>
            <scale>1 1 1</scale>
            <uri>model://meshes/visual/base_revolute_part.stl</uri>
          </mesh>
        </geometry>
        <material>
          <script>
            <name>Gazebo/White</name>
          </script>
        </material>
      </visual>
    </link>
    <joint name='crane_x7_shoulder_fixed_part_pan_joint' type='revolute'>
      <child>crane_x7_shoulder_revolute_part_link</child>
      <parent>base_link</parent>
      <axis>
        <xyz>0 0 1</xyz>
        <limit>
          <lower>-2.97132</lower>
          <upper>2.97132</upper>
          <effort>0.5</effort>
          <velocity>4.81711</velocity>
        </limit>
        <dynamics>
          <spring_reference>0</spring_reference>
          <spring_stiffness>0</spring_stiffness>
        </dynamics>
        <use_parent_model_frame>1</use_parent_model_frame>
      </axis>
    </joint>
    <link name='crane_x7_upper_arm_fixed_part_link'>
      <pose frame=''>0 0 0.105 0 -0 0</pose>
      <inertial>
        <pose frame=''>3.6e-05 0.037855 -0.00018 1.57079 -0 0</pose>
        <mass>0.130005</mass>
        <inertia>
          <ixx>3.00001</ixx>
          <ixy>0</ixy>
          <ixz>0</ixz>
          <iyy>3.00001</iyy>
          <iyz>1.32488e-11</iyz>
          <izz>3</izz>
        </inertia>
      </inertial>
      <collision name='crane_x7_upper_arm_fixed_part_link_collision'>
        <pose frame=''>0 0 0 1.57079 -0 0</pose>
        <geometry>
          <mesh>
            <scale>1 1 1</scale>
            <uri>model://meshes/collision/rotating_link_type_1_fixed_part.stl</uri>
          </mesh>
        </geometry>
      </collision>
      <collision name='crane_x7_upper_arm_fixed_part_link_fixed_joint_lump__crane_x7_upper_arm_fixed_part_joint_cover_l_link_collision_1'>
        <pose frame=''>0 0.0316 0 -1.57079 0 0</pose>
        <geometry>
          <mesh>
            <scale>1 1 1</scale>
            <uri>model://meshes/collision/joint_cover.stl</uri>
          </mesh>
        </geometry>
      </collision>
      <collision name='crane_x7_upper_arm_fixed_part_link_fixed_joint_lump__crane_x7_upper_arm_fixed_part_joint_cover_r_link_collision_2'>
        <pose frame=''>0 -0.0316 0 1.57079 -0 0</pose>
        <geometry>
          <mesh>
            <scale>1 1 1</scale>
            <uri>model://meshes/collision/joint_cover.stl</uri>
          </mesh>
        </geometry>
      </collision>
      <visual name='crane_x7_upper_arm_fixed_part_link_visual'>
        <pose frame=''>0 0 0 1.57079 -0 0</pose>
        <geometry>
          <mesh>
            <scale>1 1 1</scale>
            <uri>model://meshes/visual/rotating_link_type_1_fixed_part.stl</uri>
          </mesh>
        </geometry>
        <material>
          <script>
            <name>Gazebo/White</name>
          </script>
        </material>
      </visual>
      <visual name='crane_x7_upper_arm_fixed_part_link_fixed_joint_lump__crane_x7_upper_arm_fixed_part_joint_cover_l_link_visual_1'>
        <pose frame=''>0 0.0316 0 -1.57079 0 0</pose>
        <geometry>
          <mesh>
            <scale>1 1 1</scale>
            <uri>model://meshes/visual/joint_cover.stl</uri>
          </mesh>
        </geometry>
        <material>
          <script>
            <name>Gazebo/Red</name>
          </script>
        </material>
      </visual>
      <visual name='crane_x7_upper_arm_fixed_part_link_fixed_joint_lump__crane_x7_upper_arm_fixed_part_joint_cover_r_link_visual_2'>
        <pose frame=''>0 -0.0316 0 1.57079 -0 0</pose>
        <geometry>
          <mesh>
            <scale>1 1 1</scale>
            <uri>model://meshes/visual/joint_cover.stl</uri>
          </mesh>
        </geometry>
        <material>
          <script>
            <name>Gazebo/Red</name>
          </script>
        </material>
      </visual>
    </link>
    <joint name='crane_x7_shoulder_revolute_part_tilt_joint' type='revolute'>
      <child>crane_x7_upper_arm_fixed_part_link</child>
      <parent>crane_x7_shoulder_revolute_part_link</parent>
      <axis>
        <xyz>0 -1 0</xyz>
        <limit>
          <lower>-1.57079</lower>
          <upper>1.57079</upper>
          <effort>0.5</effort>
          <velocity>4.81711</velocity>
        </limit>
        <dynamics>
          <spring_reference>0</spring_reference>
          <spring_stiffness>0</spring_stiffness>
        </dynamics>
        <use_parent_model_frame>1</use_parent_model_frame>
      </axis>
    </joint>
    <link name='crane_x7_upper_arm_revolute_part_link'>
      <pose frame=''>0 0 0.17 0 -0 0</pose>
      <inertial>
        <pose frame=''>-0.011533 2.1e-05 0.083707 1.57079 -0 0</pose>
        <mass>0.340878</mass>
        <inertia>
          <ixx>1</ixx>
          <ixy>0</ixy>
          <ixz>0</ixz>
          <iyy>1</iyy>
          <iyz>0</iyz>
          <izz>1</izz>
        </inertia>
      </inertial>
      <collision name='crane_x7_upper_arm_revolute_part_link_collision'>
        <pose frame=''>0 0 0 0 -0 0</pose>
        <geometry>
          <mesh>
            <scale>1 1 1</scale>
            <uri>model://meshes/collision/rotating_link_type_1_revolute_part.stl</uri>
          </mesh>
        </geometry>
      </collision>
      <visual name='crane_x7_upper_arm_revolute_part_link_visual'>
        <pose frame=''>0 0 0 0 -0 0</pose>
        <geometry>
          <mesh>
            <scale>1 1 1</scale>
            <uri>model://meshes/visual/rotating_link_type_1_revolute_part.stl</uri>
          </mesh>
        </geometry>
        <material>
          <script>
            <name>Gazebo/White</name>
          </script>
        </material>
      </visual>
    </link>
    <joint name='crane_x7_upper_arm_revolute_part_twist_joint' type='revolute'>
      <child>crane_x7_upper_arm_revolute_part_link</child>
      <parent>crane_x7_upper_arm_fixed_part_link</parent>
      <axis>
        <xyz>0 0 1</xyz>
        <limit>
          <lower>-1.57079</lower>
          <upper>1.57079</upper>
          <effort>0.5</effort>
          <velocity>4.81711</velocity>
        </limit>
        <dynamics>
          <spring_reference>0</spring_reference>
          <spring_stiffness>0</spring_stiffness>
        </dynamics>
        <use_parent_model_frame>1</use_parent_model_frame>
      </axis>
    </joint>
    <link name='crane_x7_lower_arm_fixed_part_link'>
      <pose frame=''>0 0 0.355 0 -0 0</pose>
      <inertial>
        <pose frame=''>-0.00828 0.081192 -9e-05 3.14159 -0 0</pose>
        <mass>0.240634</mass>
        <inertia>
          <ixx>3.00003</ixx>
          <ixy>-3.76035e-06</ixy>
          <ixz>-7.8274e-09</ixz>
          <iyy>3</iyy>
          <iyz>-4.08053e-08</iyz>
          <izz>3.00003</izz>
        </inertia>
      </inertial>
      <collision name='crane_x7_lower_arm_fixed_part_link_collision'>
        <pose frame=''>0 0 0 1.57079 -0 0</pose>
        <geometry>
          <mesh>
            <scale>1 1 1</scale>
            <uri>model://meshes/collision/rotating_link_type_2_fixed_part.stl</uri>
          </mesh>
        </geometry>
      </collision>
      <collision name='crane_x7_lower_arm_fixed_part_link_fixed_joint_lump__crane_x7_lower_arm_fixed_part_joint_cover_l_link_collision_1'>
        <pose frame=''>0 0.025 0 -1.57079 0 0</pose>
        <geometry>
          <mesh>
            <scale>1 1 1</scale>
            <uri>model://meshes/collision/joint_cover.stl</uri>
          </mesh>
        </geometry>
      </collision>
      <collision name='crane_x7_lower_arm_fixed_part_link_fixed_joint_lump__crane_x7_lower_arm_fixed_part_joint_cover_r_link_collision_2'>
        <pose frame=''>0 -0.025 0 1.57079 -0 0</pose>
        <geometry>
          <mesh>
            <scale>1 1 1</scale>
            <uri>model://meshes/collision/joint_cover.stl</uri>
          </mesh>
        </geometry>
      </collision>
      <visual name='crane_x7_lower_arm_fixed_part_link_visual'>
        <pose frame=''>0 0 0 1.57079 -0 0</pose>
        <geometry>
          <mesh>
            <scale>1 1 1</scale>
            <uri>model://meshes/visual/rotating_link_type_2_fixed_part.stl</uri>
          </mesh>
        </geometry>
        <material>
          <script>
            <name>Gazebo/White</name>
          </script>
        </material>
      </visual>
      <visual name='crane_x7_lower_arm_fixed_part_link_fixed_joint_lump__crane_x7_lower_arm_fixed_part_joint_cover_l_link_visual_1'>
        <pose frame=''>0 0.025 0 -1.57079 0 0</pose>
        <geometry>
          <mesh>
            <scale>1 1 1</scale>
            <uri>model://meshes/visual/joint_cover.stl</uri>
          </mesh>
        </geometry>
        <material>
          <script>
            <name>Gazebo/Red</name>
          </script>
        </material>
      </visual>
      <visual name='crane_x7_lower_arm_fixed_part_link_fixed_joint_lump__crane_x7_lower_arm_fixed_part_joint_cover_r_link_visual_2'>
        <pose frame=''>0 -0.025 0 1.57079 -0 0</pose>
        <geometry>
          <mesh>
            <scale>1 1 1</scale>
            <uri>model://meshes/visual/joint_cover.stl</uri>
          </mesh>
        </geometry>
        <material>
          <script>
            <name>Gazebo/Red</name>
          </script>
        </material>
      </visual>
    </link>
    <joint name='crane_x7_upper_arm_revolute_part_rotate_joint' type='revolute'>
      <child>crane_x7_lower_arm_fixed_part_link</child>
      <parent>crane_x7_upper_arm_revolute_part_link</parent>
      <axis>
        <xyz>0 -1 0</xyz>
        <limit>
          <lower>-2.80718</lower>
          <upper>0.04141</upper>
          <effort>0.5</effort>
          <velocity>4.81711</velocity>
        </limit>
        <dynamics>
          <spring_reference>0</spring_reference>
          <spring_stiffness>0</spring_stiffness>
        </dynamics>
        <use_parent_model_frame>1</use_parent_model_frame>
      </axis>
    </joint>
    <link name='crane_x7_lower_arm_revolute_part_link'>
      <pose frame=''>0 0 0.476 0 -0 0</pose>
      <inertial>
        <pose frame=''>-2.4e-05 0.001285 0.063837 0 -0 0</pose>
        <mass>0.192709</mass>
        <inertia>
          <ixx>5</ixx>
          <ixy>-1.65436e-24</ixy>
          <ixz>0</ixz>
          <iyy>5</iyy>
          <iyz>0</iyz>
          <izz>5</izz>
        </inertia>
      </inertial>
      <collision name='crane_x7_lower_arm_revolute_part_link_collision'>
        <pose frame=''>0 0 0 0 -0 0</pose>
        <geometry>
          <mesh>
            <scale>1 1 1</scale>
            <uri>model://meshes/collision/rotating_link_type_2_revolute_part.stl</uri>
          </mesh>
        </geometry>
      </collision>
      <visual name='crane_x7_lower_arm_revolute_part_link_visual'>
        <pose frame=''>0 0 0 0 -0 0</pose>
        <geometry>
          <mesh>
            <scale>1 1 1</scale>
            <uri>model://meshes/visual/rotating_link_type_2_revolute_part.stl</uri>
          </mesh>
        </geometry>
        <material>
          <script>
            <name>Gazebo/White</name>
          </script>
        </material>
      </visual>
      <visual name='crane_x7_lower_arm_revolute_part_link_fixed_joint_lump__crane_x7_lower_arm_revolute_part_logo_symbol_l_link_visual_1'>
        <pose frame=''>0 0.0345 0.132 3.14159 1.57079 -1.57079</pose>
        <geometry>
          <mesh>
            <scale>1 1 1</scale>
            <uri>model://meshes/visual/rtcorp_logo_rabbit.stl</uri>
          </mesh>
        </geometry>
        <material>
          <script>
            <name>Gazebo/Red</name>
          </script>
        </material>
      </visual>
      <visual name='crane_x7_lower_arm_revolute_part_link_fixed_joint_lump__crane_x7_lower_arm_revolute_part_logo_symbol_r_link_visual_2'>
        <pose frame=''>0 -0.0345 0.065 -3.14159 -1.57079 -1.57079</pose>
        <geometry>
          <mesh>
            <scale>1 1 1</scale>
            <uri>model://meshes/visual/rtcorp_logo_rabbit.stl</uri>
          </mesh>
        </geometry>
        <material>
          <script>
            <name>Gazebo/Red</name>
          </script>
        </material>
      </visual>
      <visual name='crane_x7_lower_arm_revolute_part_link_fixed_joint_lump__crane_x7_lower_arm_revolute_part_logo_text_l_link_visual_3'>
        <pose frame=''>0 0.0345 0.095 3.14159 1.57079 -1.57079</pose>
        <geometry>
          <mesh>
            <scale>1 1 1</scale>
            <uri>model://meshes/visual/rtcorp_logo_name.stl</uri>
          </mesh>
        </geometry>
        <material>
          <script>
            <name>Gazebo/Red</name>
          </script>
        </material>
      </visual>
      <visual name='crane_x7_lower_arm_revolute_part_link_fixed_joint_lump__crane_x7_lower_arm_revolute_part_logo_text_r_link_visual_4'>
        <pose frame=''>0 -0.0345 0.104 -3.14159 -1.57079 -1.57079</pose>
        <geometry>
          <mesh>
            <scale>1 1 1</scale>
            <uri>model://meshes/visual/rtcorp_logo_name.stl</uri>
          </mesh>
        </geometry>
        <material>
          <script>
            <name>Gazebo/Red</name>
          </script>
        </material>
      </visual>
    </link>
    <joint name='crane_x7_lower_arm_fixed_part_joint' type='revolute'>
      <child>crane_x7_lower_arm_revolute_part_link</child>
      <parent>crane_x7_lower_arm_fixed_part_link</parent>
      <axis>
        <xyz>0 0 1</xyz>
        <limit>
          <lower>-2.77343</lower>
          <upper>1.51403</upper>
          <effort>0.5</effort>
          <velocity>4.81711</velocity>
        </limit>
        <dynamics>
          <spring_reference>0</spring_reference>
          <spring_stiffness>0</spring_stiffness>
        </dynamics>
        <use_parent_model_frame>1</use_parent_model_frame>
      </axis>
    </joint>
    <link name='crane_x7_wrist_link'>
      <pose frame=''>0 0 0.605 0 -0 0</pose>
      <inertial>
        <pose frame=''>0.005713 -0.003707 0.000781 1.57079 -0 0</pose>
        <mass>0.130549</mass>
        <inertia>
          <ixx>1</ixx>
          <ixy>0</ixy>
          <ixz>0</ixz>
          <iyy>1</iyy>
          <iyz>0</iyz>
          <izz>1</izz>
        </inertia>
      </inertial>
      <collision name='crane_x7_wrist_link_collision'>
        <pose frame=''>0 0 0 1.57079 -0 0</pose>
        <geometry>
          <mesh>
            <scale>1 1 1</scale>
            <uri>model://meshes/collision/wrist.stl</uri>
          </mesh>
        </geometry>
      </collision>
      <visual name='crane_x7_wrist_link_visual'>
        <pose frame=''>0 0 0 1.57079 -0 0</pose>
        <geometry>
          <mesh>
            <scale>1 1 1</scale>
            <uri>model://meshes/visual/wrist.stl</uri>
          </mesh>
        </geometry>
        <material>
          <script>
            <name>Gazebo/White</name>
          </script>
        </material>
      </visual>
    </link>
    <joint name='crane_x7_lower_arm_revolute_part_joint' type='revolute'>
      <child>crane_x7_wrist_link</child>
      <parent>crane_x7_lower_arm_revolute_part_link</parent>
      <axis>
        <xyz>0 -1 0</xyz>
        <limit>
          <lower>-1.57079</lower>
          <upper>1.57079</upper>
          <effort>0.5</effort>
          <velocity>4.81711</velocity>
        </limit>
        <dynamics>
          <spring_reference>0</spring_reference>
          <spring_stiffness>0</spring_stiffness>
        </dynamics>
        <use_parent_model_frame>1</use_parent_model_frame>
      </axis>
    </joint>
    <link name='crane_x7_gripper_base_link'>
      <pose frame=''>0 0 0.624 0 -0 0</pose>
      <inertial>
        <pose frame=''>0.000425 -0.000896 0.018691 0 -0 0</pose>
        <mass>0.119807</mass>
        <inertia>
          <ixx>1</ixx>
          <ixy>0</ixy>
          <ixz>0</ixz>
          <iyy>1</iyy>
          <iyz>0</iyz>
          <izz>1</izz>
        </inertia>
      </inertial>
      <collision name='crane_x7_gripper_base_link_collision'>
        <pose frame=''>0 0 0 0 -0 0</pose>
        <geometry>
          <mesh>
            <scale>1 1 1</scale>
            <uri>model://meshes/collision/wide_two_finger_gripper_actuator.stl</uri>
          </mesh>
        </geometry>
      </collision>
      <visual name='crane_x7_gripper_base_link_visual'>
        <pose frame=''>0 0 0 0 -0 0</pose>
        <geometry>
          <mesh>
            <scale>1 1 1</scale>
            <uri>model://meshes/visual/wide_two_finger_gripper_actuator.stl</uri>
          </mesh>
        </geometry>
        <material>
          <script>
            <name>Gazebo/Red</name>
          </script>
        </material>
      </visual>
    </link>
    <joint name='crane_x7_wrist_joint' type='revolute'>
      <child>crane_x7_gripper_base_link</child>
      <parent>crane_x7_wrist_link</parent>
      <axis>
        <xyz>0 0 1</xyz>
        <limit>
          <lower>-2.96365</lower>
          <upper>2.97132</upper>
          <effort>0.5</effort>
          <velocity>4.81711</velocity>
        </limit>
        <dynamics>
          <spring_reference>0</spring_reference>
          <spring_stiffness>0</spring_stiffness>
        </dynamics>
        <use_parent_model_frame>1</use_parent_model_frame>
      </axis>
    </joint>
    <link name='crane_x7_gripper_finger_a_link'>
      <pose frame=''>-0.012 0 0.648 0 -0 0</pose>
      <inertial>
        <pose frame=''>-0.002987 0.030318 0.003073 1.57079 -0 0</pose>
        <mass>0.015617</mass>
        <inertia>
          <ixx>1</ixx>
          <ixy>0</ixy>
          <ixz>0</ixz>
          <iyy>1</iyy>
          <iyz>0</iyz>
          <izz>1</izz>
        </inertia>
      </inertial>
      <collision name='crane_x7_gripper_finger_a_link_collision'>
        <pose frame=''>0 0 0 1.57079 -0 0</pose>
        <geometry>
          <mesh>
            <scale>1 1 1</scale>
            <uri>model://meshes/collision/wide_two_finger_gripper_finger_a.stl</uri>
          </mesh>
        </geometry>
      </collision>
      <visual name='crane_x7_gripper_finger_a_link_visual'>
        <pose frame=''>0 0 0 1.57079 -0 0</pose>
        <geometry>
          <mesh>
            <scale>1 1 1</scale>
            <uri>model://meshes/visual/wide_two_finger_gripper_finger_a.stl</uri>
          </mesh>
        </geometry>
        <material>
          <script>
            <name>Gazebo/Red</name>
          </script>
        </material>
      </visual>
    </link>
    <joint name='crane_x7_gripper_finger_a_joint' type='revolute'>
      <child>crane_x7_gripper_finger_a_link</child>
      <parent>crane_x7_gripper_base_link</parent>
      <axis>
        <xyz>0 -1 0</xyz>
        <limit>
          <lower>0.0046</lower>
          <upper>1.62601</upper>
          <effort>0.5</effort>
          <velocity>4.81711</velocity>
        </limit>
        <dynamics>
          <spring_reference>0</spring_reference>
          <spring_stiffness>0</spring_stiffness>
        </dynamics>
        <use_parent_model_frame>1</use_parent_model_frame>
      </axis>
    </joint>
    <link name='crane_x7_gripper_finger_b_link'>
      <pose frame=''>0.012 0 0.648 0 -0 0</pose>
      <inertial>
        <pose frame=''>0.003058 0.031215 0.002548 1.57079 -0 0</pose>
        <mass>0.014417</mass>
        <inertia>
          <ixx>1</ixx>
          <ixy>0</ixy>
          <ixz>0</ixz>
          <iyy>1</iyy>
          <iyz>0</iyz>
          <izz>1</izz>
        </inertia>
      </inertial>
      <collision name='crane_x7_gripper_finger_b_link_collision'>
        <pose frame=''>0 0 0 1.57079 -0 0</pose>
        <geometry>
          <mesh>
            <scale>1 1 1</scale>
            <uri>model://meshes/collision/wide_two_finger_gripper_finger_b.stl</uri>
          </mesh>
        </geometry>
      </collision>
      <visual name='crane_x7_gripper_finger_b_link_visual'>
        <pose frame=''>0 0 0 1.57079 -0 0</pose>
        <geometry>
          <mesh>
            <scale>1 1 1</scale>
            <uri>model://meshes/visual/wide_two_finger_gripper_finger_b.stl</uri>
          </mesh>
        </geometry>
        <material>
          <script>
            <name>Gazebo/Red</name>
          </script>
        </material>
      </visual>
    </link>
    <joint name='crane_x7_gripper_finger_b_joint' type='revolute'>
      <child>crane_x7_gripper_finger_b_link</child>
      <parent>crane_x7_gripper_base_link</parent>
      <axis>
        <xyz>0 1 0</xyz>
        <limit>
          <lower>0.0046</lower>
          <upper>1.62601</upper>
          <effort>0.5</effort>
          <velocity>4.81711</velocity>
        </limit>
        <dynamics>
          <spring_reference>0</spring_reference>
          <spring_stiffness>0</spring_stiffness>
        </dynamics>
        <use_parent_model_frame>1</use_parent_model_frame>
      </axis>
    </joint>
  </model>
</sdf>
