<?xml version="1.0"?>

<robot xmlns:xacro="http://ros.org/wiki/xacro">
  <xacro:property name="M_PI" value="3.14159"/>
  <xacro:property name="SCALE_MM" value="0.001"/>
  <xacro:property name="SCALE_CM" value="0.01"/>

  <xacro:property name="NAME_JOINT_BASE" value="crane_x7_shoulder_fixed_part_mount_joint"/>
  <xacro:property name="NAME_JOINT_1" value="crane_x7_shoulder_fixed_part_pan_joint"/>
  <xacro:property name="NAME_JOINT_2" value="crane_x7_shoulder_revolute_part_tilt_joint"/>
  <xacro:property name="NAME_JOINT_3" value="crane_x7_upper_arm_revolute_part_twist_joint"/>
  <xacro:property name="NAME_JOINT_4" value="crane_x7_upper_arm_revolute_part_rotate_joint"/>
  <xacro:property name="NAME_JOINT_5" value="crane_x7_lower_arm_fixed_part_joint"/>
  <xacro:property name="NAME_JOINT_6" value="crane_x7_lower_arm_revolute_part_joint"/>
  <xacro:property name="NAME_JOINT_7" value="crane_x7_wrist_joint"/>

  <xacro:property name="NAME_LINK_BASE" value="crane_x7_shoulder_fixed_part_link"/>
  <xacro:property name="NAME_LINK_1" value="crane_x7_shoulder_revolute_part_link"/>
  <xacro:property name="NAME_LINK_2" value="crane_x7_upper_arm_fixed_part_link"/>
  <xacro:property name="NAME_LINK_3" value="crane_x7_upper_arm_revolute_part_link"/>
  <xacro:property name="NAME_LINK_4" value="crane_x7_lower_arm_fixed_part_link"/>
  <xacro:property name="NAME_LINK_5" value="crane_x7_lower_arm_revolute_part_link"/>
  <xacro:property name="NAME_LINK_6" value="crane_x7_wrist_link"/>

  <xacro:property name="NAME_JOINT_COVER_2_L" value="crane_x7_upper_arm_fixed_part_joint_cover_l_joint"/>
  <xacro:property name="NAME_JOINT_COVER_2_R" value="crane_x7_upper_arm_fixed_part_joint_cover_r_joint"/>
  <xacro:property name="NAME_JOINT_COVER_4_L" value="crane_x7_lower_arm_fixed_part_joint_cover_l_joint"/>
  <xacro:property name="NAME_JOINT_COVER_4_R" value="crane_x7_lower_arm_fixed_part_joint_cover_r_joint"/>

  <xacro:property name="NAME_LINK_COVER_2_L" value="crane_x7_upper_arm_fixed_part_joint_cover_l_link"/>
  <xacro:property name="NAME_LINK_COVER_2_R" value="crane_x7_upper_arm_fixed_part_joint_cover_r_link"/>
  <xacro:property name="NAME_LINK_COVER_4_L" value="crane_x7_lower_arm_fixed_part_joint_cover_l_link"/>
  <xacro:property name="NAME_LINK_COVER_4_R" value="crane_x7_lower_arm_fixed_part_joint_cover_r_link"/>

  <xacro:property name="NAME_LOGO" value="crane_x7_lower_arm_revolute_part"/>

  <!-- Macro for the standard CRANE-X7 configuration -->
  <xacro:macro name="crane_x7_arm"
      params="parent
              end_effector_base_link
              base_color
              shoulder_color
              shoulder_joint_cover_color
              upper_arm_upper_color
              upper_arm_lower_color
              elbow_joint_cover_color
              lower_arm_upper_color
              lower_arm_lower_color
              wrist_color
              joints_vlimit
              shoulder_llimit
              shoulder_ulimit
              logos_definition
              *origin">

    <!-- crane_x7_joint_base -->
    <joint name="${NAME_JOINT_BASE}" type="fixed">
      <xacro:insert_block name="origin"/>
      <parent link="${parent}"/>
      <child link="${NAME_LINK_BASE}"/>
    </joint>

    <!-- crane_x7_link_base -->
    <link name="${NAME_LINK_BASE}">
      <visual>
        <origin xyz="0 0 0" rpy="0 0 0"/>
        <geometry>
          <mesh filename="package://crane_x7_description/meshes/visual/base_fixed_part.stl"
              scale="1 1 1"/>
        </geometry>
        <material name="${base_color}"/>
      </visual>

      <collision>
        <origin xyz="0 0 0" rpy="0 0 0"/>
        <geometry>
          <mesh filename="package://crane_x7_description/meshes/collision/base_fixed_part.stl"
              scale="1 1 1"/>
        </geometry>
      </collision>

      <inertial>
        <mass value="0.387313"/>
        <origin xyz="-0.00669 0.000049 0.017868" rpy="0 0 0"/>
        <inertia ixx="1" ixy="0.0" ixz="0.0"
          iyy="1" iyz="0.0"
          izz="1"/>
      </inertial>
    </link>

    <!-- crane_x7_joint_1 -->
    <joint name="${NAME_JOINT_1}" type="revolute">
      <origin xyz="0 0 0.036" rpy="0 0 0"/>
      <axis xyz="0 0 1"/>
      <limit effort="0.5" velocity="${joints_vlimit}" lower="${shoulder_llimit}" upper="${shoulder_ulimit}"/>
      <parent link="${NAME_LINK_BASE}"/>
      <child link="${NAME_LINK_1}"/>
    </joint>

    <!-- crane_x7_link_1 -->
    <link name="${NAME_LINK_1}">
      <visual>
        <origin xyz="0 0 0" rpy="0 0 ${M_PI}"/>
        <geometry>
          <mesh filename="package://crane_x7_description/meshes/visual/base_revolute_part.stl"
              scale="1 1 1"/>
        </geometry>
        <material name="${shoulder_color}"/>
      </visual>

      <collision>
        <origin xyz="0 0 0" rpy="0 0 ${M_PI}"/>
        <geometry>
          <mesh filename="package://crane_x7_description/meshes/collision/base_revolute_part.stl"
              scale="1 1 1"/>
        </geometry>
      </collision>

      <inertial>
        <mass value="0.235377"/>
        <origin xyz="0.000013 -0.000407 0.046345" rpy="0 0 0"/>
        <inertia ixx="1" ixy="0.0" ixz="0.0"
          iyy="1" iyz="0.0"
          izz="1"/>
      </inertial>
    </link>

    <!-- crane_x7_joint_2 -->
    <joint name="${NAME_JOINT_2}" type="revolute">
      <origin xyz="0 0 0.064" rpy="0 0 0"/>
      <axis xyz="0 -1 0"/>
      <limit effort="0.5" velocity="${joints_vlimit}" lower="-${M_PI/2}" upper="${M_PI/2}"/>
      <parent link="${NAME_LINK_1}"/>
      <child link="${NAME_LINK_2}"/>
    </joint>

    <!-- crane_x7_link_2 -->
    <link name="${NAME_LINK_2}">
      <visual>
        <origin xyz="0 0 0" rpy="${M_PI/2} 0 0"/>
        <geometry>
          <mesh filename="package://crane_x7_description/meshes/visual/rotating_link_type_1_fixed_part.stl"
              scale="1 1 1"/>
        </geometry>
        <material name="${upper_arm_upper_color}"/>
      </visual>

      <collision>
        <origin xyz="0 0 0" rpy="${M_PI/2} 0 0"/>
        <geometry>
          <mesh filename="package://crane_x7_description/meshes/collision/rotating_link_type_1_fixed_part.stl"
              scale="1 1 1"/>
        </geometry>
      </collision>

      <inertial>
        <mass value="0.120005"/>
        <origin xyz="0.000036 0.037855 -0.00018" rpy="${M_PI/2} 0 0"/>
        <inertia ixx="1" ixy="0.0" ixz="0.0"
          iyy="1" iyz="0.0"
          izz="1"/>
      </inertial>
    </link>

    <!-- crane_x7_joint_cover_2_l -->
    <joint name="${NAME_JOINT_COVER_2_L}" type="fixed">
      <parent link="${NAME_LINK_2}"/>
      <child link="${NAME_LINK_COVER_2_L}"/>
      <origin xyz="0 0.0316 0" rpy="0 0 0"/>
    </joint>

    <!-- crane_x7_link_cover_2_l -->
    <link name="${NAME_LINK_COVER_2_L}">
      <visual>
        <origin xyz="0 0 0" rpy="-${M_PI/2} 0 0"/>
        <geometry>
          <mesh filename="package://crane_x7_description/meshes/visual/joint_cover.stl"
              scale="1 1 1"/>
        </geometry>
        <material name="${shoulder_joint_cover_color}"/>
      </visual>
      <collision>
        <origin xyz="0 0 0" rpy="-${M_PI/2} 0 0"/>
        <geometry>
          <mesh filename="package://crane_x7_description/meshes/collision/joint_cover.stl"
              scale="1 1 1"/>
        </geometry>
      </collision>
      <inertial>
        <mass value="0.005"/>
        <origin xyz="0.000036 0.037855 -0.00018" rpy="${M_PI/2} 0 0"/>
        <inertia ixx="1" ixy="0.0" ixz="0.0"
          iyy="1" iyz="0.0"
          izz="1"/>
      </inertial>
    </link>

    <!-- crane_x7_joint_cover_2_r -->
    <joint name="${NAME_JOINT_COVER_2_R}" type="fixed">
      <parent link="${NAME_LINK_2}"/>
      <child link="${NAME_LINK_COVER_2_R}"/>
      <origin xyz="0 -0.0316 0" rpy="0 0 0"/>
    </joint>

    <!-- crane_x7_link_cover_2_r -->
    <link name="${NAME_LINK_COVER_2_R}">
      <visual>
        <origin xyz="0 0 0" rpy="${M_PI/2} 0 0"/>
        <geometry>
          <mesh filename="package://crane_x7_description/meshes/visual/joint_cover.stl"
              scale="1 1 1"/>
        </geometry>
        <material name="${shoulder_joint_cover_color}"/>
      </visual>
      <collision>
        <origin xyz="0 0 0" rpy="${M_PI/2} 0 0"/>
        <geometry>
          <mesh filename="package://crane_x7_description/meshes/collision/joint_cover.stl"
              scale="1 1 1"/>
        </geometry>
      </collision>
      <inertial>
        <mass value="0.005"/>
        <origin xyz="0.000036 0.037855 -0.00018" rpy="${M_PI/2} 0 0"/>
        <inertia ixx="1" ixy="0.0" ixz="0.0"
          iyy="1" iyz="0.0"
          izz="1"/>
      </inertial>
    </link>

    <!-- crane_x7_joint_3 -->
    <joint name="${NAME_JOINT_3}" type="revolute">
      <origin xyz="0 0 0.065" rpy="0 0 0"/>
      <axis xyz="0 0 1"/>
      <limit effort="0.5"
          velocity="${joints_vlimit}"
          lower="-${M_PI/2}"
          upper="${M_PI/2}"/>
      <parent link="${NAME_LINK_2}"/>
      <child link="${NAME_LINK_3}"/>
    </joint>

    <!-- crane_x7_link_3 -->
    <link name="${NAME_LINK_3}">
      <visual>
        <origin xyz="0 0 0" rpy="0 0 0"/>
        <geometry>
          <mesh filename="package://crane_x7_description/meshes/visual/rotating_link_type_1_revolute_part.stl"
              scale="1 1 1"/>
        </geometry>
        <material name="${upper_arm_lower_color}"/>
      </visual>

      <collision>
        <origin xyz="0 0 0" rpy="0 0 0"/>
        <geometry>
          <mesh filename="package://crane_x7_description/meshes/collision/rotating_link_type_1_revolute_part.stl"
              scale="1 1 1"/>
        </geometry>
      </collision>

      <inertial>
        <mass value="0.340878"/>
        <origin xyz="-0.011533 0.000021 0.083707" rpy="${M_PI/2} 0 0"/>
        <inertia ixx="1" ixy="0.0" ixz="0.0"
          iyy="1" iyz="0.0"
          izz="1"/>
      </inertial>
    </link>

    <!-- crane_x7_joint_4 -->
    <joint name="${NAME_JOINT_4}" type="revolute">
      <origin xyz="0 0 0.185" rpy="0 0 0"/>
      <axis xyz="0 -1 0"/>
      <limit effort="0.5"
          velocity="${joints_vlimit}"
          lower="-2.80718"
          upper="0.04141"/>
      <parent link="${NAME_LINK_3}"/>
      <child link="${NAME_LINK_4}"/>
    </joint>

    <!-- crane_x7_link_4 -->
    <link name="${NAME_LINK_4}">
      <visual>
        <origin xyz="0 0 0" rpy="${M_PI/2} 0 0"/>
        <geometry>
          <mesh filename="package://crane_x7_description/meshes/visual/rotating_link_type_2_fixed_part.stl"
              scale="1 1 1"/>
        </geometry>
        <material name="${lower_arm_upper_color}"/>
      </visual>

      <collision>
        <origin xyz="0 0 0" rpy="${M_PI/2} 0 0"/>
        <geometry>
          <mesh filename="package://crane_x7_description/meshes/collision/rotating_link_type_2_fixed_part.stl"
              scale="1 1 1"/>
        </geometry>
      </collision>

      <inertial>
        <mass value="0.230634"/>
        <origin xyz="-0.008641 0.083071 -0.000086" rpy="${M_PI} 0 0"/>
        <inertia ixx="1" ixy="0.0" ixz="0.0"
          iyy="1" iyz="0.0"
          izz="1"/>
      </inertial>
    </link>

    <!-- crane_x7_joint_cover_4_l -->
    <joint name="${NAME_JOINT_COVER_4_L}" type="fixed">
      <parent link="${NAME_LINK_4}"/>
      <child link="${NAME_LINK_COVER_4_L}"/>
      <origin xyz="0 0.025 0" rpy="0 0 0"/>
    </joint>

    <!-- crane_x7_link_cover_4_l -->
    <link name="${NAME_LINK_COVER_4_L}">
      <visual>
        <origin xyz="0 0 0" rpy="-${M_PI/2} 0 0"/>
        <geometry>
          <mesh filename="package://crane_x7_description/meshes/visual/joint_cover.stl"
              scale="1 1 1"/>
        </geometry>
        <material name="${elbow_joint_cover_color}"/>
      </visual>
      <collision>
        <origin xyz="0 0 0" rpy="-${M_PI/2} 0 0"/>
        <geometry>
          <mesh filename="package://crane_x7_description/meshes/collision/joint_cover.stl"
              scale="1 1 1"/>
        </geometry>
      </collision>
      <inertial>
        <mass value="0.005"/>
        <origin xyz="0.000036 0.037855 -0.00018" rpy="${M_PI/2} 0 0"/>
        <inertia ixx="1" ixy="0.0" ixz="0.0"
          iyy="1" iyz="0.0"
          izz="1"/>
      </inertial>
    </link>

    <!-- crane_x7_joint_cover_4_r -->
    <joint name="${NAME_JOINT_COVER_4_R}" type="fixed">
      <parent link="${NAME_LINK_4}"/>
      <child link="${NAME_LINK_COVER_4_R}"/>
      <origin xyz="0 -0.025 0" rpy="0 0 0"/>
    </joint>

    <!-- crane_x7_link_cover_4_r -->
    <link name="${NAME_LINK_COVER_4_R}">
      <visual>
        <origin xyz="0 0 0" rpy="${M_PI/2} 0 0"/>
        <geometry>
          <mesh filename="package://crane_x7_description/meshes/visual/joint_cover.stl"
              scale="1 1 1"/>
        </geometry>
        <material name="${elbow_joint_cover_color}"/>
      </visual>
      <collision>
        <origin xyz="0 0 0" rpy="${M_PI/2} 0 0"/>
        <geometry>
          <mesh filename="package://crane_x7_description/meshes/collision/joint_cover.stl"
              scale="1 1 1"/>
        </geometry>
      </collision>
      <inertial>
        <mass value="0.005"/>
        <origin xyz="0.000036 0.037855 -0.00018" rpy="${M_PI/2} 0 0"/>
        <inertia ixx="1" ixy="0.0" ixz="0.0"
          iyy="1" iyz="0.0"
          izz="1"/>
      </inertial>
    </link>

    <!-- crane_x7_joint_5 -->
    <joint name="${NAME_JOINT_5}" type="revolute">
      <origin xyz="0 0 0.121" rpy="0 0 0"/>
      <axis xyz="0 0 1"/>
      <limit effort="0.5" velocity="${joints_vlimit}" lower="-2.77343" upper="1.51403"/>
      <parent link="${NAME_LINK_4}"/>
      <child link="${NAME_LINK_5}"/>
    </joint>

    <!-- crane_x7_link_5 -->
    <link name="${NAME_LINK_5}">
      <visual>
        <origin xyz="0 0 0" rpy="0 0 0"/>
        <geometry>
          <mesh filename="package://crane_x7_description/meshes/visual/rotating_link_type_2_revolute_part.stl"
              scale="1 1 1"/>
        </geometry>
        <material name="${lower_arm_lower_color}"/>
      </visual>

      <collision>
        <origin xyz="0 0 0" rpy="0 0 0"/>
        <geometry>
          <mesh filename="package://crane_x7_description/meshes/collision/rotating_link_type_2_revolute_part.stl"
              scale="1 1 1"/>
        </geometry>
      </collision>

      <inertial>
        <mass value="0.192709"/>
        <origin xyz="-0.000024 0.001285 0.063837" rpy="0 0 0"/>
        <inertia ixx="1" ixy="0.0" ixz="0.0"
          iyy="1" iyz="0.0"
          izz="1"/>
      </inertial>
    </link>

    <!-- logo -->
    <xacro:include filename="${logos_definition}"/>
    <crane_x7_logos 
      parent="${NAME_LINK_5}"
      name="${NAME_LOGO}"/>

    <!-- crane_x7_joint_6 -->
    <joint name="${NAME_JOINT_6}" type="revolute">
      <origin xyz="0 0 0.129" rpy="0 0 0"/>
      <axis xyz="0 -1 0"/>
      <limit effort="0.5" velocity="${joints_vlimit}" lower="-${M_PI/2}" upper="${M_PI/2}"/>
      <parent link="${NAME_LINK_5}"/>
      <child link="${NAME_LINK_6}"/>
    </joint>

    <!-- crane_x7_link_6 -->
    <link name="${NAME_LINK_6}">
      <visual>
        <origin xyz="0 0 0" rpy="${M_PI/2} 0 0"/>
        <geometry>
          <mesh filename="package://crane_x7_description/meshes/visual/wrist.stl"
              scale="1 1 1"/>
        </geometry>
        <material name="${wrist_color}"/>
      </visual>

      <collision>
        <origin xyz="0 0 0" rpy="${M_PI/2} 0 0"/>
        <geometry>
          <mesh filename="package://crane_x7_description/meshes/collision/wrist.stl"
              scale="1 1 1"/>
        </geometry>
      </collision>

      <inertial>
        <mass value="0.130549"/>
        <origin xyz="0.005713 -0.003707 0.000781" rpy="${M_PI/2} 0 0"/>
        <inertia ixx="1" ixy="0.0" ixz="0.0"
          iyy="1" iyz="0.0"
          izz="1"/>
      </inertial>
    </link>

    <!-- crane_x7_joint_7 -->
    <joint name="${NAME_JOINT_7}" type="revolute">
      <origin xyz="0 0 0.019" rpy="0 0 0"/>
      <axis xyz="0 0 1"/>
      <limit effort="0.5" velocity="${joints_vlimit}" lower="-2.96365" upper="2.97132"/>
      <parent link="${NAME_LINK_6}"/>
      <child link="${end_effector_base_link}"/>
    </joint>

  </xacro:macro>

</robot>
